Workbook

Sheet READ ME 

Sheet VEGETATION
C2: FVS Spreadsheet Tool for the South Western Slopes IBRA region v2.0
C4: Only fill in the | D4: BLUE (press F2 to enter cell) | E4: and | F4: GREY | H4: cells | I4: ORANGE cells are field headings
C6: Site name & location: | D6: Date of survey: | E6: Survey Id. and/or Site Id. codes: | F6: Species code. Enter species codes in the grey column below. Refer to sheet Sp_score_ref for a full list and special codes. | G6: C/A code. Refer to the table to the left for C/A values. | H6: The cells below will autofill with the species' full name | I6: The cells below will autofill with the species' regional Significance Rating | J6: Non-grass species | K6: Level A species (BB 1 to 7) | L6: Level A species (no C/A score 2) | M6: Level A species (no C/A score 1) | N6: Level B species (BB 1 to 7) | O6: Level C species (no C/A score 2) | P6: Level C species (no C/A score 1) | Q6: Level C species (BB 1 to 7) | R6: Level C species (no C/A score 2) | S6: Level C species (no C/A score 1) | T6: Level X weed species (BB 1 to 7) | U6: Level X weed species (no C/A score 2) | V6: Level X weed species (no C/A score 1) | W6: Level Y weed species (BB 1 to 7) | X6: Level Y weed species (no C/A score 2) | Y6: Level Y weed species (no C/A score 1) | Z6: Level Z weed species (level 3) (C/A score 1 to 7) | AA6: Level Z weed species (level 3) (no C/A score 2) | AB6: Level Z weed species (level 3) (no C/A score 1)
H7: =VLOOKUP(F7,Sp_score_ref!$A$2:$C$1517,2,FALSE) -> #N/A | I7: =VLOOKUP(F7,Sp_score_ref!$A$2:$C$1517,3,FALSE) -> #N/A | K7: =IF($I7 = "A", 1, "0") -> #N/A | L7: =IF(AND($I7 = "A", $G7 <> 2), 1, "0") -> #N/A | M7: =IF(AND($I7 = "A", $G7 <> 1), 1, "0") -> #N/A | N7: =IF($I7 = "B", 1, "0") -> #N/A | O7: =IF(AND($I7 = "B", $G7 <> 2), 1, "0") -> #N/A | P7: =IF(AND($I7 = "B", $G7 <> 1), 1, "0") -> #N/A | Q7: =IF($I7 = "C", 1, "0") -> #N/A | R7: =IF(AND($I7 = "C", $G7 <> 2), 1, "0") -> #N/A | S7: =IF(AND($I7 = "C", $G7 <> 1), 1, "0") -> #N/A | T7: =IF($I7 = "X", 1, "0") -> #N/A | U7: =IF(AND($I7 = "X", $G7 <> 2), 1, "0") -> #N/A | V7: =IF(AND($I7 = "X", $G7 <> 1), 1, "0") -> #N/A | W7: =IF($I7 = "Y", 1, "0") -> #N/A | X7: =IF(AND($I7 = "Y", $G7 <> 2), 1, "0") -> #N/A | Y7: =IF(AND($I7 = "Y", $G7 <> 1), 1, "0") -> #N/A | Z7: =IF($I7 = "Z", 1, "0") -> #N/A | AA7: =IF(AND($I7 = "Z", $G7 <> 2), 1, "0") -> #N/A | AB7: =IF(AND($I7 = "Z", $G7 <> 1), 1, "0") -> #N/A
C8: Plot information | H8: =VLOOKUP(F8,Sp_score_ref!$A$2:$C$1517,2,FALSE) -> #N/A | I8: =VLOOKUP(F8,Sp_score_ref!$A$2:$C$1517,3,FALSE) -> #N/A | K8: =IF($I8 = "A", 1, "0") -> #N/A | L8: =IF(AND($I8 = "A", $G8 <> 2), 1, "0") -> #N/A | M8: =IF(AND($I8 = "A", $G8 <> 1), 1, "0") -> #N/A | N8: =IF($I8 = "B", 1, "0") -> #N/A | O8: =IF(AND($I8 = "B", $G8 <> 2), 1, "0") -> #N/A | P8: =IF(AND($I8 = "B", $G8 <> 1), 1, "0") -> #N/A | Q8: =IF($I8 = "C", 1, "0") -> #N/A | R8: =IF(AND($I8 = "C", $G8 <> 2), 1, "0") -> #N/A | S8: =IF(AND($I8 = "C", $G8 <> 1), 1, "0") -> #N/A | T8: =IF($I8 = "X", 1, "0") -> #N/A | U8: =IF(AND($I8 = "X", $G8 <> 2), 1, "0") -> #N/A | V8: =IF(AND($I8 = "X", $G8 <> 1), 1, "0") -> #N/A | W8: =IF($I8 = "Y", 1, "0") -> #N/A | X8: =IF(AND($I8 = "Y", $G8 <> 2), 1, "0") -> #N/A | Y8: =IF(AND($I8 = "Y", $G8 <> 1), 1, "0") -> #N/A | Z8: =IF($I8 = "Z", 1, "0") -> #N/A | AA8: =IF(AND($I8 = "Z", $G8 <> 2), 1, "0") -> #N/A | AB8: =IF(AND($I8 = "Z", $G8 <> 1), 1, "0") -> #N/A
C9: Datum and Zone | H9: =VLOOKUP(F9,Sp_score_ref!$A$2:$C$1517,2,FALSE) -> #N/A | I9: =VLOOKUP(F9,Sp_score_ref!$A$2:$C$1517,3,FALSE) -> #N/A | K9: =IF($I9 = "A", 1, "0") -> #N/A | L9: =IF(AND($I9 = "A", $G9 <> 2), 1, "0") -> #N/A | M9: =IF(AND($I9 = "A", $G9 <> 1), 1, "0") -> #N/A | N9: =IF($I9 = "B", 1, "0") -> #N/A | O9: =IF(AND($I9 = "B", $G9 <> 2), 1, "0") -> #N/A | P9: =IF(AND($I9 = "B", $G9 <> 1), 1, "0") -> #N/A | Q9: =IF($I9 = "C", 1, "0") -> #N/A | R9: =IF(AND($I9 = "C", $G9 <> 2), 1, "0") -> #N/A | S9: =IF(AND($I9 = "C", $G9 <> 1), 1, "0") -> #N/A | T9: =IF($I9 = "X", 1, "0") -> #N/A | U9: =IF(AND($I9 = "X", $G9 <> 2), 1, "0") -> #N/A | V9: =IF(AND($I9 = "X", $G9 <> 1), 1, "0") -> #N/A | W9: =IF($I9 = "Y", 1, "0") -> #N/A | X9: =IF(AND($I9 = "Y", $G9 <> 2), 1, "0") -> #N/A | Y9: =IF(AND($I9 = "Y", $G9 <> 1), 1, "0") -> #N/A | Z9: =IF($I9 = "Z", 1, "0") -> #N/A | AA9: =IF(AND($I9 = "Z", $G9 <> 2), 1, "0") -> #N/A | AB9: =IF(AND($I9 = "Z", $G9 <> 1), 1, "0") -> #N/A
C10: AMG Easting | H10: =VLOOKUP(F10,Sp_score_ref!$A$2:$C$1517,2,FALSE) -> #N/A | I10: =VLOOKUP(F10,Sp_score_ref!$A$2:$C$1517,3,FALSE) -> #N/A | K10: =IF($I10 = "A", 1, "0") -> #N/A | L10: =IF(AND($I10 = "A", $G10 <> 2), 1, "0") -> #N/A | M10: =IF(AND($I10 = "A", $G10 <> 1), 1, "0") -> #N/A | N10: =IF($I10 = "B", 1, "0") -> #N/A | O10: =IF(AND($I10 = "B", $G10 <> 2), 1, "0") -> #N/A | P10: =IF(AND($I10 = "B", $G10 <> 1), 1, "0") -> #N/A | Q10: =IF($I10 = "C", 1, "0") -> #N/A | R10: =IF(AND($I10 = "C", $G10 <> 2), 1, "0") -> #N/A | S10: =IF(AND($I10 = "C", $G10 <> 1), 1, "0") -> #N/A | T10: =IF($I10 = "X", 1, "0") -> #N/A | U10: =IF(AND($I10 = "X", $G10 <> 2), 1, "0") -> #N/A | V10: =IF(AND($I10 = "X", $G10 <> 1), 1, "0") -> #N/A | W10: =IF($I10 = "Y", 1, "0") -> #N/A | X10: =IF(AND($I10 = "Y", $G10 <> 2), 1, "0") -> #N/A | Y10: =IF(AND($I10 = "Y", $G10 <> 1), 1, "0") -> #N/A | Z10: =IF($I10 = "Z", 1, "0") -> #N/A | AA10: =IF(AND($I10 = "Z", $G10 <> 2), 1, "0") -> #N/A | AB10: =IF(AND($I10 = "Z", $G10 <> 1), 1, "0") -> #N/A
C11: AMG Northing | H11: =VLOOKUP(F11,Sp_score_ref!$A$2:$C$1517,2,FALSE) -> #N/A | I11: =VLOOKUP(F11,Sp_score_ref!$A$2:$C$1517,3,FALSE) -> #N/A | K11: =IF($I11 = "A", 1, "0") -> #N/A | L11: =IF(AND($I11 = "A", $G11 <> 2), 1, "0") -> #N/A | M11: =IF(AND($I11 = "A", $G11 <> 1), 1, "0") -> #N/A | N11: =IF($I11 = "B", 1, "0") -> #N/A | O11: =IF(AND($I11 = "B", $G11 <> 2), 1, "0") -> #N/A | P11: =IF(AND($I11 = "B", $G11 <> 1), 1, "0") -> #N/A | Q11: =IF($I11 = "C", 1, "0") -> #N/A | R11: =IF(AND($I11 = "C", $G11 <> 2), 1, "0") -> #N/A | S11: =IF(AND($I11 = "C", $G11 <> 1), 1, "0") -> #N/A | T11: =IF($I11 = "X", 1, "0") -> #N/A | U11: =IF(AND($I11 = "X", $G11 <> 2), 1, "0") -> #N/A | V11: =IF(AND($I11 = "X", $G11 <> 1), 1, "0") -> #N/A | W11: =IF($I11 = "Y", 1, "0") -> #N/A | X11: =IF(AND($I11 = "Y", $G11 <> 2), 1, "0") -> #N/A | Y11: =IF(AND($I11 = "Y", $G11 <> 1), 1, "0") -> #N/A | Z11: =IF($I11 = "Z", 1, "0") -> #N/A | AA11: =IF(AND($I11 = "Z", $G11 <> 2), 1, "0") -> #N/A | AB11: =IF(AND($I11 = "Z", $G11 <> 1), 1, "0") -> #N/A
H12: =VLOOKUP(F12,Sp_score_ref!$A$2:$C$1517,2,FALSE) -> #N/A | I12: =VLOOKUP(F12,Sp_score_ref!$A$2:$C$1517,3,FALSE) -> #N/A | K12: =IF($I12 = "A", 1, "0") -> #N/A | L12: =IF(AND($I12 = "A", $G12 <> 2), 1, "0") -> #N/A | M12: =IF(AND($I12 = "A", $G12 <> 1), 1, "0") -> #N/A | N12: =IF($I12 = "B", 1, "0") -> #N/A | O12: =IF(AND($I12 = "B", $G12 <> 2), 1, "0") -> #N/A | P12: =IF(AND($I12 = "B", $G12 <> 1), 1, "0") -> #N/A | Q12: =IF($I12 = "C", 1, "0") -> #N/A | R12: =IF(AND($I12 = "C", $G12 <> 2), 1, "0") -> #N/A | S12: =IF(AND($I12 = "C", $G12 <> 1), 1, "0") -> #N/A | T12: =IF($I12 = "X", 1, "0") -> #N/A | U12: =IF(AND($I12 = "X", $G12 <> 2), 1, "0") -> #N/A | V12: =IF(AND($I12 = "X", $G12 <> 1), 1, "0") -> #N/A | W12: =IF($I12 = "Y", 1, "0") -> #N/A | X12: =IF(AND($I12 = "Y", $G12 <> 2), 1, "0") -> #N/A | Y12: =IF(AND($I12 = "Y", $G12 <> 1), 1, "0") -> #N/A | Z12: =IF($I12 = "Z", 1, "0") -> #N/A | AA12: =IF(AND($I12 = "Z", $G12 <> 2), 1, "0") -> #N/A | AB12: =IF(AND($I12 = "Z", $G12 <> 1), 1, "0") -> #N/A
B13: Cover / abundance scores for data entry | H13: =VLOOKUP(F13,Sp_score_ref!$A$2:$C$1517,2,FALSE) -> #N/A | I13: =VLOOKUP(F13,Sp_score_ref!$A$2:$C$1517,3,FALSE) -> #N/A | K13: =IF($I13 = "A", 1, "0") -> #N/A | L13: =IF(AND($I13 = "A", $G13 <> 2), 1, "0") -> #N/A | M13: =IF(AND($I13 = "A", $G13 <> 1), 1, "0") -> #N/A | N13: =IF($I13 = "B", 1, "0") -> #N/A | O13: =IF(AND($I13 = "B", $G13 <> 2), 1, "0") -> #N/A | P13: =IF(AND($I13 = "B", $G13 <> 1), 1, "0") -> #N/A | Q13: =IF($I13 = "C", 1, "0") -> #N/A | R13: =IF(AND($I13 = "C", $G13 <> 2), 1, "0") -> #N/A | S13: =IF(AND($I13 = "C", $G13 <> 1), 1, "0") -> #N/A | T13: =IF($I13 = "X", 1, "0") -> #N/A | U13: =IF(AND($I13 = "X", $G13 <> 2), 1, "0") -> #N/A | V13: =IF(AND($I13 = "X", $G13 <> 1), 1, "0") -> #N/A | W13: =IF($I13 = "Y", 1, "0") -> #N/A | X13: =IF(AND($I13 = "Y", $G13 <> 2), 1, "0") -> #N/A | Y13: =IF(AND($I13 = "Y", $G13 <> 1), 1, "0") -> #N/A | Z13: =IF($I13 = "Z", 1, "0") -> #N/A | AA13: =IF(AND($I13 = "Z", $G13 <> 2), 1, "0") -> #N/A | AB13: =IF(AND($I13 = "Z", $G13 <> 1), 1, "0") -> #N/A
B14: 1 | C14: < 5 % cover and solitary (< 4 individuals) | H14: =VLOOKUP(F14,Sp_score_ref!$A$2:$C$1517,2,FALSE) -> #N/A | I14: =VLOOKUP(F14,Sp_score_ref!$A$2:$C$1517,3,FALSE) -> #N/A | K14: =IF($I14 = "A", 1, "0") -> #N/A | L14: =IF(AND($I14 = "A", $G14 <> 2), 1, "0") -> #N/A | M14: =IF(AND($I14 = "A", $G14 <> 1), 1, "0") -> #N/A | N14: =IF($I14 = "B", 1, "0") -> #N/A | O14: =IF(AND($I14 = "B", $G14 <> 2), 1, "0") -> #N/A | P14: =IF(AND($I14 = "B", $G14 <> 1), 1, "0") -> #N/A | Q14: =IF($I14 = "C", 1, "0") -> #N/A | R14: =IF(AND($I14 = "C", $G14 <> 2), 1, "0") -> #N/A | S14: =IF(AND($I14 = "C", $G14 <> 1), 1, "0") -> #N/A | T14: =IF($I14 = "X", 1, "0") -> #N/A | U14: =IF(AND($I14 = "X", $G14 <> 2), 1, "0") -> #N/A | V14: =IF(AND($I14 = "X", $G14 <> 1), 1, "0") -> #N/A | W14: =IF($I14 = "Y", 1, "0") -> #N/A | X14: =IF(AND($I14 = "Y", $G14 <> 2), 1, "0") -> #N/A | Y14: =IF(AND($I14 = "Y", $G14 <> 1), 1, "0") -> #N/A | Z14: =IF($I14 = "Z", 1, "0") -> #N/A | AA14: =IF(AND($I14 = "Z", $G14 <> 2), 1, "0") -> #N/A | AB14: =IF(AND($I14 = "Z", $G14 <> 1), 1, "0") -> #N/A
B15: 2 | C15: < 5 % cover and few (4-15 individuals) | H15: =VLOOKUP(F15,Sp_score_ref!$A$2:$C$1517,2,FALSE) -> #N/A | I15: =VLOOKUP(F15,Sp_score_ref!$A$2:$C$1517,3,FALSE) -> #N/A | K15: =IF($I15 = "A", 1, "0") -> #N/A | L15: =IF(AND($I15 = "A", $G15 <> 2), 1, "0") -> #N/A | M15: =IF(AND($I15 = "A", $G15 <> 1), 1, "0") -> #N/A | N15: =IF($I15 = "B", 1, "0") -> #N/A | O15: =IF(AND($I15 = "B", $G15 <> 2), 1, "0") -> #N/A | P15: =IF(AND($I15 = "B", $G15 <> 1), 1, "0") -> #N/A | Q15: =IF($I15 = "C", 1, "0") -> #N/A | R15: =IF(AND($I15 = "C", $G15 <> 2), 1, "0") -> #N/A | S15: =IF(AND($I15 = "C", $G15 <> 1), 1, "0") -> #N/A | T15: =IF($I15 = "X", 1, "0") -> #N/A | U15: =IF(AND($I15 = "X", $G15 <> 2), 1, "0") -> #N/A | V15: =IF(AND($I15 = "X", $G15 <> 1), 1, "0") -> #N/A | W15: =IF($I15 = "Y", 1, "0") -> #N/A | X15: =IF(AND($I15 = "Y", $G15 <> 2), 1, "0") -> #N/A | Y15: =IF(AND($I15 = "Y", $G15 <> 1), 1, "0") -> #N/A | Z15: =IF($I15 = "Z", 1, "0") -> #N/A | AA15: =IF(AND($I15 = "Z", $G15 <> 2), 1, "0") -> #N/A | AB15: =IF(AND($I15 = "Z", $G15 <> 1), 1, "0") -> #N/A
B16: 3 | C16: < 5 % cover and numerous (> 15 individuals) | H16: =VLOOKUP(F16,Sp_score_ref!$A$2:$C$1517,2,FALSE) -> #N/A | I16: =VLOOKUP(F16,Sp_score_ref!$A$2:$C$1517,3,FALSE) -> #N/A | K16: =IF($I16 = "A", 1, "0") -> #N/A | L16: =IF(AND($I16 = "A", $G16 <> 2), 1, "0") -> #N/A | M16: =IF(AND($I16 = "A", $G16 <> 1), 1, "0") -> #N/A | N16: =IF($I16 = "B", 1, "0") -> #N/A | O16: =IF(AND($I16 = "B", $G16 <> 2), 1, "0") -> #N/A | P16: =IF(AND($I16 = "B", $G16 <> 1), 1, "0") -> #N/A | Q16: =IF($I16 = "C", 1, "0") -> #N/A | R16: =IF(AND($I16 = "C", $G16 <> 2), 1, "0") -> #N/A | S16: =IF(AND($I16 = "C", $G16 <> 1), 1, "0") -> #N/A | T16: =IF($I16 = "X", 1, "0") -> #N/A | U16: =IF(AND($I16 = "X", $G16 <> 2), 1, "0") -> #N/A | V16: =IF(AND($I16 = "X", $G16 <> 1), 1, "0") -> #N/A | W16: =IF($I16 = "Y", 1, "0") -> #N/A | X16: =IF(AND($I16 = "Y", $G16 <> 2), 1, "0") -> #N/A | Y16: =IF(AND($I16 = "Y", $G16 <> 1), 1, "0") -> #N/A | Z16: =IF($I16 = "Z", 1, "0") -> #N/A | AA16: =IF(AND($I16 = "Z", $G16 <> 2), 1, "0") -> #N/A | AB16: =IF(AND($I16 = "Z", $G16 <> 1), 1, "0") -> #N/A
B17: 4 | C17: 5 % < 25 % cover | H17: =VLOOKUP(F17,Sp_score_ref!$A$2:$C$1517,2,FALSE) -> #N/A | I17: =VLOOKUP(F17,Sp_score_ref!$A$2:$C$1517,3,FALSE) -> #N/A | K17: =IF($I17 = "A", 1, "0") -> #N/A | L17: =IF(AND($I17 = "A", $G17 <> 2), 1, "0") -> #N/A | M17: =IF(AND($I17 = "A", $G17 <> 1), 1, "0") -> #N/A | N17: =IF($I17 = "B", 1, "0") -> #N/A | O17: =IF(AND($I17 = "B", $G17 <> 2), 1, "0") -> #N/A | P17: =IF(AND($I17 = "B", $G17 <> 1), 1, "0") -> #N/A | Q17: =IF($I17 = "C", 1, "0") -> #N/A | R17: =IF(AND($I17 = "C", $G17 <> 2), 1, "0") -> #N/A | S17: =IF(AND($I17 = "C", $G17 <> 1), 1, "0") -> #N/A | T17: =IF($I17 = "X", 1, "0") -> #N/A | U17: =IF(AND($I17 = "X", $G17 <> 2), 1, "0") -> #N/A | V17: =IF(AND($I17 = "X", $G17 <> 1), 1, "0") -> #N/A | W17: =IF($I17 = "Y", 1, "0") -> #N/A | X17: =IF(AND($I17 = "Y", $G17 <> 2), 1, "0") -> #N/A | Y17: =IF(AND($I17 = "Y", $G17 <> 1), 1, "0") -> #N/A | Z17: =IF($I17 = "Z", 1, "0") -> #N/A | AA17: =IF(AND($I17 = "Z", $G17 <> 2), 1, "0") -> #N/A | AB17: =IF(AND($I17 = "Z", $G17 <> 1), 1, "0") -> #N/A
B18: 5 | C18: 25 % < 50 % cover | H18: =VLOOKUP(F18,Sp_score_ref!$A$2:$C$1517,2,FALSE) -> #N/A | I18: =VLOOKUP(F18,Sp_score_ref!$A$2:$C$1517,3,FALSE) -> #N/A | K18: =IF($I18 = "A", 1, "0") -> #N/A | L18: =IF(AND($I18 = "A", $G18 <> 2), 1, "0") -> #N/A | M18: =IF(AND($I18 = "A", $G18 <> 1), 1, "0") -> #N/A | N18: =IF($I18 = "B", 1, "0") -> #N/A | O18: =IF(AND($I18 = "B", $G18 <> 2), 1, "0") -> #N/A | P18: =IF(AND($I18 = "B", $G18 <> 1), 1, "0") -> #N/A | Q18: =IF($I18 = "C", 1, "0") -> #N/A | R18: =IF(AND($I18 = "C", $G18 <> 2), 1, "0") -> #N/A | S18: =IF(AND($I18 = "C", $G18 <> 1), 1, "0") -> #N/A | T18: =IF($I18 = "X", 1, "0") -> #N/A | U18: =IF(AND($I18 = "X", $G18 <> 2), 1, "0") -> #N/A | V18: =IF(AND($I18 = "X", $G18 <> 1), 1, "0") -> #N/A | W18: =IF($I18 = "Y", 1, "0") -> #N/A | X18: =IF(AND($I18 = "Y", $G18 <> 2), 1, "0") -> #N/A | Y18: =IF(AND($I18 = "Y", $G18 <> 1), 1, "0") -> #N/A | Z18: =IF($I18 = "Z", 1, "0") -> #N/A | AA18: =IF(AND($I18 = "Z", $G18 <> 2), 1, "0") -> #N/A | AB18: =IF(AND($I18 = "Z", $G18 <> 1), 1, "0") -> #N/A
B19: 6 | C19: 50 % < 75 % cover | H19: =VLOOKUP(F19,Sp_score_ref!$A$2:$C$1517,2,FALSE) -> #N/A | I19: =VLOOKUP(F19,Sp_score_ref!$A$2:$C$1517,3,FALSE) -> #N/A | K19: =IF($I19 = "A", 1, "0") -> #N/A | L19: =IF(AND($I19 = "A", $G19 <> 2), 1, "0") -> #N/A | M19: =IF(AND($I19 = "A", $G19 <> 1), 1, "0") -> #N/A | N19: =IF($I19 = "B", 1, "0") -> #N/A | O19: =IF(AND($I19 = "B", $G19 <> 2), 1, "0") -> #N/A | P19: =IF(AND($I19 = "B", $G19 <> 1), 1, "0") -> #N/A | Q19: =IF($I19 = "C", 1, "0") -> #N/A | R19: =IF(AND($I19 = "C", $G19 <> 2), 1, "0") -> #N/A | S19: =IF(AND($I19 = "C", $G19 <> 1), 1, "0") -> #N/A | T19: =IF($I19 = "X", 1, "0") -> #N/A | U19: =IF(AND($I19 = "X", $G19 <> 2), 1, "0") -> #N/A | V19: =IF(AND($I19 = "X", $G19 <> 1), 1, "0") -> #N/A | W19: =IF($I19 = "Y", 1, "0") -> #N/A | X19: =IF(AND($I19 = "Y", $G19 <> 2), 1, "0") -> #N/A | Y19: =IF(AND($I19 = "Y", $G19 <> 1), 1, "0") -> #N/A | Z19: =IF($I19 = "Z", 1, "0") -> #N/A | AA19: =IF(AND($I19 = "Z", $G19 <> 2), 1, "0") -> #N/A | AB19: =IF(AND($I19 = "Z", $G19 <> 1), 1, "0") -> #N/A
B20: 7 | C20: ≥ 75 % cover | H20: =VLOOKUP(F20,Sp_score_ref!$A$2:$C$1517,2,FALSE) -> #N/A | I20: =VLOOKUP(F20,Sp_score_ref!$A$2:$C$1517,3,FALSE) -> #N/A | K20: =IF($I20 = "A", 1, "0") -> #N/A | L20: =IF(AND($I20 = "A", $G20 <> 2), 1, "0") -> #N/A | M20: =IF(AND($I20 = "A", $G20 <> 1), 1, "0") -> #N/A | N20: =IF($I20 = "B", 1, "0") -> #N/A | O20: =IF(AND($I20 = "B", $G20 <> 2), 1, "0") -> #N/A | P20: =IF(AND($I20 = "B", $G20 <> 1), 1, "0") -> #N/A | Q20: =IF($I20 = "C", 1, "0") -> #N/A | R20: =IF(AND($I20 = "C", $G20 <> 2), 1, "0") -> #N/A | S20: =IF(AND($I20 = "C", $G20 <> 1), 1, "0") -> #N/A | T20: =IF($I20 = "X", 1, "0") -> #N/A | U20: =IF(AND($I20 = "X", $G20 <> 2), 1, "0") -> #N/A | V20: =IF(AND($I20 = "X", $G20 <> 1), 1, "0") -> #N/A | W20: =IF($I20 = "Y", 1, "0") -> #N/A | X20: =IF(AND($I20 = "Y", $G20 <> 2), 1, "0") -> #N/A | Y20: =IF(AND($I20 = "Y", $G20 <> 1), 1, "0") -> #N/A | Z20: =IF($I20 = "Z", 1, "0") -> #N/A | AA20: =IF(AND($I20 = "Z", $G20 <> 2), 1, "0") -> #N/A | AB20: =IF(AND($I20 = "Z", $G20 <> 1), 1, "0") -> #N/A
H21: =VLOOKUP(F21,Sp_score_ref!$A$2:$C$1517,2,FALSE) -> #N/A | I21: =VLOOKUP(F21,Sp_score_ref!$A$2:$C$1517,3,FALSE) -> #N/A | K21: =IF($I21 = "A", 1, "0") -> #N/A | L21: =IF(AND($I21 = "A", $G21 <> 2), 1, "0") -> #N/A | M21: =IF(AND($I21 = "A", $G21 <> 1), 1, "0") -> #N/A | N21: =IF($I21 = "B", 1, "0") -> #N/A | O21: =IF(AND($I21 = "B", $G21 <> 2), 1, "0") -> #N/A | P21: =IF(AND($I21 = "B", $G21 <> 1), 1, "0") -> #N/A | Q21: =IF($I21 = "C", 1, "0") -> #N/A | R21: =IF(AND($I21 = "C", $G21 <> 2), 1, "0") -> #N/A | S21: =IF(AND($I21 = "C", $G21 <> 1), 1, "0") -> #N/A | T21: =IF($I21 = "X", 1, "0") -> #N/A | U21: =IF(AND($I21 = "X", $G21 <> 2), 1, "0") -> #N/A | V21: =IF(AND($I21 = "X", $G21 <> 1), 1, "0") -> #N/A | W21: =IF($I21 = "Y", 1, "0") -> #N/A | X21: =IF(AND($I21 = "Y", $G21 <> 2), 1, "0") -> #N/A | Y21: =IF(AND($I21 = "Y", $G21 <> 1), 1, "0") -> #N/A | Z21: =IF($I21 = "Z", 1, "0") -> #N/A | AA21: =IF(AND($I21 = "Z", $G21 <> 2), 1, "0") -> #N/A | AB21: =IF(AND($I21 = "Z", $G21 <> 1), 1, "0") -> #N/A
B22: RED cells contain data entry instructions (see below) | H22: =VLOOKUP(F22,Sp_score_ref!$A$2:$C$1517,2,FALSE) -> #N/A | I22: =VLOOKUP(F22,Sp_score_ref!$A$2:$C$1517,3,FALSE) -> #N/A | K22: =IF($I22 = "A", 1, "0") -> #N/A | L22: =IF(AND($I22 = "A", $G22 <> 2), 1, "0") -> #N/A | M22: =IF(AND($I22 = "A", $G22 <> 1), 1, "0") -> #N/A | N22: =IF($I22 = "B", 1, "0") -> #N/A | O22: =IF(AND($I22 = "B", $G22 <> 2), 1, "0") -> #N/A | P22: =IF(AND($I22 = "B", $G22 <> 1), 1, "0") -> #N/A | Q22: =IF($I22 = "C", 1, "0") -> #N/A | R22: =IF(AND($I22 = "C", $G22 <> 2), 1, "0") -> #N/A | S22: =IF(AND($I22 = "C", $G22 <> 1), 1, "0") -> #N/A | T22: =IF($I22 = "X", 1, "0") -> #N/A | U22: =IF(AND($I22 = "X", $G22 <> 2), 1, "0") -> #N/A | V22: =IF(AND($I22 = "X", $G22 <> 1), 1, "0") -> #N/A | W22: =IF($I22 = "Y", 1, "0") -> #N/A | X22: =IF(AND($I22 = "Y", $G22 <> 2), 1, "0") -> #N/A | Y22: =IF(AND($I22 = "Y", $G22 <> 1), 1, "0") -> #N/A | Z22: =IF($I22 = "Z", 1, "0") -> #N/A | AA22: =IF(AND($I22 = "Z", $G22 <> 2), 1, "0") -> #N/A | AB22: =IF(AND($I22 = "Z", $G22 <> 1), 1, "0") -> #N/A
H23: =VLOOKUP(F23,Sp_score_ref!$A$2:$C$1517,2,FALSE) -> #N/A | I23: =VLOOKUP(F23,Sp_score_ref!$A$2:$C$1517,3,FALSE) -> #N/A | K23: =IF($I23 = "A", 1, "0") -> #N/A | L23: =IF(AND($I23 = "A", $G23 <> 2), 1, "0") -> #N/A | M23: =IF(AND($I23 = "A", $G23 <> 1), 1, "0") -> #N/A | N23: =IF($I23 = "B", 1, "0") -> #N/A | O23: =IF(AND($I23 = "B", $G23 <> 2), 1, "0") -> #N/A | P23: =IF(AND($I23 = "B", $G23 <> 1), 1, "0") -> #N/A | Q23: =IF($I23 = "C", 1, "0") -> #N/A | R23: =IF(AND($I23 = "C", $G23 <> 2), 1, "0") -> #N/A | S23: =IF(AND($I23 = "C", $G23 <> 1), 1, "0") -> #N/A | T23: =IF($I23 = "X", 1, "0") -> #N/A | U23: =IF(AND($I23 = "X", $G23 <> 2), 1, "0") -> #N/A | V23: =IF(AND($I23 = "X", $G23 <> 1), 1, "0") -> #N/A | W23: =IF($I23 = "Y", 1, "0") -> #N/A | X23: =IF(AND($I23 = "Y", $G23 <> 2), 1, "0") -> #N/A | Y23: =IF(AND($I23 = "Y", $G23 <> 1), 1, "0") -> #N/A | Z23: =IF($I23 = "Z", 1, "0") -> #N/A | AA23: =IF(AND($I23 = "Z", $G23 <> 2), 1, "0") -> #N/A | AB23: =IF(AND($I23 = "Z", $G23 <> 1), 1, "0") -> #N/A
H24: =VLOOKUP(F24,Sp_score_ref!$A$2:$C$1517,2,FALSE) -> #N/A | I24: =VLOOKUP(F24,Sp_score_ref!$A$2:$C$1517,3,FALSE) -> #N/A | K24: =IF($I24 = "A", 1, "0") -> #N/A | L24: =IF(AND($I24 = "A", $G24 <> 2), 1, "0") -> #N/A | M24: =IF(AND($I24 = "A", $G24 <> 1), 1, "0") -> #N/A | N24: =IF($I24 = "B", 1, "0") -> #N/A | O24: =IF(AND($I24 = "B", $G24 <> 2), 1, "0") -> #N/A | P24: =IF(AND($I24 = "B", $G24 <> 1), 1, "0") -> #N/A | Q24: =IF($I24 = "C", 1, "0") -> #N/A | R24: =IF(AND($I24 = "C", $G24 <> 2), 1, "0") -> #N/A | S24: =IF(AND($I24 = "C", $G24 <> 1), 1, "0") -> #N/A | T24: =IF($I24 = "X", 1, "0") -> #N/A | U24: =IF(AND($I24 = "X", $G24 <> 2), 1, "0") -> #N/A | V24: =IF(AND($I24 = "X", $G24 <> 1), 1, "0") -> #N/A | W24: =IF($I24 = "Y", 1, "0") -> #N/A | X24: =IF(AND($I24 = "Y", $G24 <> 2), 1, "0") -> #N/A | Y24: =IF(AND($I24 = "Y", $G24 <> 1), 1, "0") -> #N/A | Z24: =IF($I24 = "Z", 1, "0") -> #N/A | AA24: =IF(AND($I24 = "Z", $G24 <> 2), 1, "0") -> #N/A | AB24: =IF(AND($I24 = "Z", $G24 <> 1), 1, "0") -> #N/A
B25: YELLOW cells return analysis values (see below) | H25: =VLOOKUP(F25,Sp_score_ref!$A$2:$C$1517,2,FALSE) -> #N/A | I25: =VLOOKUP(F25,Sp_score_ref!$A$2:$C$1517,3,FALSE) -> #N/A | K25: =IF($I25 = "A", 1, "0") -> #N/A | L25: =IF(AND($I25 = "A", $G25 <> 2), 1, "0") -> #N/A | M25: =IF(AND($I25 = "A", $G25 <> 1), 1, "0") -> #N/A | N25: =IF($I25 = "B", 1, "0") -> #N/A | O25: =IF(AND($I25 = "B", $G25 <> 2), 1, "0") -> #N/A | P25: =IF(AND($I25 = "B", $G25 <> 1), 1, "0") -> #N/A | Q25: =IF($I25 = "C", 1, "0") -> #N/A | R25: =IF(AND($I25 = "C", $G25 <> 2), 1, "0") -> #N/A | S25: =IF(AND($I25 = "C", $G25 <> 1), 1, "0") -> #N/A | T25: =IF($I25 = "X", 1, "0") -> #N/A | U25: =IF(AND($I25 = "X", $G25 <> 2), 1, "0") -> #N/A | V25: =IF(AND($I25 = "X", $G25 <> 1), 1, "0") -> #N/A | W25: =IF($I25 = "Y", 1, "0") -> #N/A | X25: =IF(AND($I25 = "Y", $G25 <> 2), 1, "0") -> #N/A | Y25: =IF(AND($I25 = "Y", $G25 <> 1), 1, "0") -> #N/A | Z25: =IF($I25 = "Z", 1, "0") -> #N/A | AA25: =IF(AND($I25 = "Z", $G25 <> 2), 1, "0") -> #N/A | AB25: =IF(AND($I25 = "Z", $G25 <> 1), 1, "0") -> #N/A
H26: =VLOOKUP(F26,Sp_score_ref!$A$2:$C$1517,2,FALSE) -> #N/A | I26: =VLOOKUP(F26,Sp_score_ref!$A$2:$C$1517,3,FALSE) -> #N/A | K26: =IF($I26 = "A", 1, "0") -> #N/A | L26: =IF(AND($I26 = "A", $G26 <> 2), 1, "0") -> #N/A | M26: =IF(AND($I26 = "A", $G26 <> 1), 1, "0") -> #N/A | N26: =IF($I26 = "B", 1, "0") -> #N/A | O26: =IF(AND($I26 = "B", $G26 <> 2), 1, "0") -> #N/A | P26: =IF(AND($I26 = "B", $G26 <> 1), 1, "0") -> #N/A | Q26: =IF($I26 = "C", 1, "0") -> #N/A | R26: =IF(AND($I26 = "C", $G26 <> 2), 1, "0") -> #N/A | S26: =IF(AND($I26 = "C", $G26 <> 1), 1, "0") -> #N/A | T26: =IF($I26 = "X", 1, "0") -> #N/A | U26: =IF(AND($I26 = "X", $G26 <> 2), 1, "0") -> #N/A | V26: =IF(AND($I26 = "X", $G26 <> 1), 1, "0") -> #N/A | W26: =IF($I26 = "Y", 1, "0") -> #N/A | X26: =IF(AND($I26 = "Y", $G26 <> 2), 1, "0") -> #N/A | Y26: =IF(AND($I26 = "Y", $G26 <> 1), 1, "0") -> #N/A | Z26: =IF($I26 = "Z", 1, "0") -> #N/A | AA26: =IF(AND($I26 = "Z", $G26 <> 2), 1, "0") -> #N/A | AB26: =IF(AND($I26 = "Z", $G26 <> 1), 1, "0") -> #N/A
H27: =VLOOKUP(F27,Sp_score_ref!$A$2:$C$1517,2,FALSE) -> #N/A | I27: =VLOOKUP(F27,Sp_score_ref!$A$2:$C$1517,3,FALSE) -> #N/A | K27: =IF($I27 = "A", 1, "0") -> #N/A | L27: =IF(AND($I27 = "A", $G27 <> 2), 1, "0") -> #N/A | M27: =IF(AND($I27 = "A", $G27 <> 1), 1, "0") -> #N/A | N27: =IF($I27 = "B", 1, "0") -> #N/A | O27: =IF(AND($I27 = "B", $G27 <> 2), 1, "0") -> #N/A | P27: =IF(AND($I27 = "B", $G27 <> 1), 1, "0") -> #N/A | Q27: =IF($I27 = "C", 1, "0") -> #N/A | R27: =IF(AND($I27 = "C", $G27 <> 2), 1, "0") -> #N/A | S27: =IF(AND($I27 = "C", $G27 <> 1), 1, "0") -> #N/A | T27: =IF($I27 = "X", 1, "0") -> #N/A | U27: =IF(AND($I27 = "X", $G27 <> 2), 1, "0") -> #N/A | V27: =IF(AND($I27 = "X", $G27 <> 1), 1, "0") -> #N/A | W27: =IF($I27 = "Y", 1, "0") -> #N/A | X27: =IF(AND($I27 = "Y", $G27 <> 2), 1, "0") -> #N/A | Y27: =IF(AND($I27 = "Y", $G27 <> 1), 1, "0") -> #N/A | Z27: =IF($I27 = "Z", 1, "0") -> #N/A | AA27: =IF(AND($I27 = "Z", $G27 <> 2), 1, "0") -> #N/A | AB27: =IF(AND($I27 = "Z", $G27 <> 1), 1, "0") -> #N/A
B28: For tips on entering data, see the next sheet | H28: =VLOOKUP(F28,Sp_score_ref!$A$2:$C$1517,2,FALSE) -> #N/A | I28: =VLOOKUP(F28,Sp_score_ref!$A$2:$C$1517,3,FALSE) -> #N/A | K28: =IF($I28 = "A", 1, "0") -> #N/A | L28: =IF(AND($I28 = "A", $G28 <> 2), 1, "0") -> #N/A | M28: =IF(AND($I28 = "A", $G28 <> 1), 1, "0") -> #N/A | N28: =IF($I28 = "B", 1, "0") -> #N/A | O28: =IF(AND($I28 = "B", $G28 <> 2), 1, "0") -> #N/A | P28: =IF(AND($I28 = "B", $G28 <> 1), 1, "0") -> #N/A | Q28: =IF($I28 = "C", 1, "0") -> #N/A | R28: =IF(AND($I28 = "C", $G28 <> 2), 1, "0") -> #N/A | S28: =IF(AND($I28 = "C", $G28 <> 1), 1, "0") -> #N/A | T28: =IF($I28 = "X", 1, "0") -> #N/A | U28: =IF(AND($I28 = "X", $G28 <> 2), 1, "0") -> #N/A | V28: =IF(AND($I28 = "X", $G28 <> 1), 1, "0") -> #N/A | W28: =IF($I28 = "Y", 1, "0") -> #N/A | X28: =IF(AND($I28 = "Y", $G28 <> 2), 1, "0") -> #N/A | Y28: =IF(AND($I28 = "Y", $G28 <> 1), 1, "0") -> #N/A | Z28: =IF($I28 = "Z", 1, "0") -> #N/A | AA28: =IF(AND($I28 = "Z", $G28 <> 2), 1, "0") -> #N/A | AB28: =IF(AND($I28 = "Z", $G28 <> 1), 1, "0") -> #N/A
H29: =VLOOKUP(F29,Sp_score_ref!$A$2:$C$1517,2,FALSE) -> #N/A | I29: =VLOOKUP(F29,Sp_score_ref!$A$2:$C$1517,3,FALSE) -> #N/A | K29: =IF($I29 = "A", 1, "0") -> #N/A | L29: =IF(AND($I29 = "A", $G29 <> 2), 1, "0") -> #N/A | M29: =IF(AND($I29 = "A", $G29 <> 1), 1, "0") -> #N/A | N29: =IF($I29 = "B", 1, "0") -> #N/A | O29: =IF(AND($I29 = "B", $G29 <> 2), 1, "0") -> #N/A | P29: =IF(AND($I29 = "B", $G29 <> 1), 1, "0") -> #N/A | Q29: =IF($I29 = "C", 1, "0") -> #N/A | R29: =IF(AND($I29 = "C", $G29 <> 2), 1, "0") -> #N/A | S29: =IF(AND($I29 = "C", $G29 <> 1), 1, "0") -> #N/A | T29: =IF($I29 = "X", 1, "0") -> #N/A | U29: =IF(AND($I29 = "X", $G29 <> 2), 1, "0") -> #N/A | V29: =IF(AND($I29 = "X", $G29 <> 1), 1, "0") -> #N/A | W29: =IF($I29 = "Y", 1, "0") -> #N/A | X29: =IF(AND($I29 = "Y", $G29 <> 2), 1, "0") -> #N/A | Y29: =IF(AND($I29 = "Y", $G29 <> 1), 1, "0") -> #N/A | Z29: =IF($I29 = "Z", 1, "0") -> #N/A | AA29: =IF(AND($I29 = "Z", $G29 <> 2), 1, "0") -> #N/A | AB29: =IF(AND($I29 = "Z", $G29 <> 1), 1, "0") -> #N/A
H30: =VLOOKUP(F30,Sp_score_ref!$A$2:$C$1517,2,FALSE) -> #N/A | I30: =VLOOKUP(F30,Sp_score_ref!$A$2:$C$1517,3,FALSE) -> #N/A | K30: =IF($I30 = "A", 1, "0") -> #N/A | L30: =IF(AND($I30 = "A", $G30 <> 2), 1, "0") -> #N/A | M30: =IF(AND($I30 = "A", $G30 <> 1), 1, "0") -> #N/A | N30: =IF($I30 = "B", 1, "0") -> #N/A | O30: =IF(AND($I30 = "B", $G30 <> 2), 1, "0") -> #N/A | P30: =IF(AND($I30 = "B", $G30 <> 1), 1, "0") -> #N/A | Q30: =IF($I30 = "C", 1, "0") -> #N/A | R30: =IF(AND($I30 = "C", $G30 <> 2), 1, "0") -> #N/A | S30: =IF(AND($I30 = "C", $G30 <> 1), 1, "0") -> #N/A | T30: =IF($I30 = "X", 1, "0") -> #N/A | U30: =IF(AND($I30 = "X", $G30 <> 2), 1, "0") -> #N/A | V30: =IF(AND($I30 = "X", $G30 <> 1), 1, "0") -> #N/A | W30: =IF($I30 = "Y", 1, "0") -> #N/A | X30: =IF(AND($I30 = "Y", $G30 <> 2), 1, "0") -> #N/A | Y30: =IF(AND($I30 = "Y", $G30 <> 1), 1, "0") -> #N/A | Z30: =IF($I30 = "Z", 1, "0") -> #N/A | AA30: =IF(AND($I30 = "Z", $G30 <> 2), 1, "0") -> #N/A | AB30: =IF(AND($I30 = "Z", $G30 <> 1), 1, "0") -> #N/A
C31: Information for assessment purposes only | H31: =VLOOKUP(F31,Sp_score_ref!$A$2:$C$1517,2,FALSE) -> #N/A | I31: =VLOOKUP(F31,Sp_score_ref!$A$2:$C$1517,3,FALSE) -> #N/A | K31: =IF($I31 = "A", 1, "0") -> #N/A | L31: =IF(AND($I31 = "A", $G31 <> 2), 1, "0") -> #N/A | M31: =IF(AND($I31 = "A", $G31 <> 1), 1, "0") -> #N/A | N31: =IF($I31 = "B", 1, "0") -> #N/A | O31: =IF(AND($I31 = "B", $G31 <> 2), 1, "0") -> #N/A | P31: =IF(AND($I31 = "B", $G31 <> 1), 1, "0") -> #N/A | Q31: =IF($I31 = "C", 1, "0") -> #N/A | R31: =IF(AND($I31 = "C", $G31 <> 2), 1, "0") -> #N/A | S31: =IF(AND($I31 = "C", $G31 <> 1), 1, "0") -> #N/A | T31: =IF($I31 = "X", 1, "0") -> #N/A | U31: =IF(AND($I31 = "X", $G31 <> 2), 1, "0") -> #N/A | V31: =IF(AND($I31 = "X", $G31 <> 1), 1, "0") -> #N/A | W31: =IF($I31 = "Y", 1, "0") -> #N/A | X31: =IF(AND($I31 = "Y", $G31 <> 2), 1, "0") -> #N/A | Y31: =IF(AND($I31 = "Y", $G31 <> 1), 1, "0") -> #N/A | Z31: =IF($I31 = "Z", 1, "0") -> #N/A | AA31: =IF(AND($I31 = "Z", $G31 <> 2), 1, "0") -> #N/A | AB31: =IF(AND($I31 = "Z", $G31 <> 1), 1, "0") -> #N/A
C32: Litter (cover %) | H32: =VLOOKUP(F32,Sp_score_ref!$A$2:$C$1517,2,FALSE) -> #N/A | I32: =VLOOKUP(F32,Sp_score_ref!$A$2:$C$1517,3,FALSE) -> #N/A | K32: =IF($I32 = "A", 1, "0") -> #N/A | L32: =IF(AND($I32 = "A", $G32 <> 2), 1, "0") -> #N/A | M32: =IF(AND($I32 = "A", $G32 <> 1), 1, "0") -> #N/A | N32: =IF($I32 = "B", 1, "0") -> #N/A | O32: =IF(AND($I32 = "B", $G32 <> 2), 1, "0") -> #N/A | P32: =IF(AND($I32 = "B", $G32 <> 1), 1, "0") -> #N/A | Q32: =IF($I32 = "C", 1, "0") -> #N/A | R32: =IF(AND($I32 = "C", $G32 <> 2), 1, "0") -> #N/A | S32: =IF(AND($I32 = "C", $G32 <> 1), 1, "0") -> #N/A | T32: =IF($I32 = "X", 1, "0") -> #N/A | U32: =IF(AND($I32 = "X", $G32 <> 2), 1, "0") -> #N/A | V32: =IF(AND($I32 = "X", $G32 <> 1), 1, "0") -> #N/A | W32: =IF($I32 = "Y", 1, "0") -> #N/A | X32: =IF(AND($I32 = "Y", $G32 <> 2), 1, "0") -> #N/A | Y32: =IF(AND($I32 = "Y", $G32 <> 1), 1, "0") -> #N/A | Z32: =IF($I32 = "Z", 1, "0") -> #N/A | AA32: =IF(AND($I32 = "Z", $G32 <> 2), 1, "0") -> #N/A | AB32: =IF(AND($I32 = "Z", $G32 <> 1), 1, "0") -> #N/A
C33: Bare ground (% cover) | H33: =VLOOKUP(F33,Sp_score_ref!$A$2:$C$1517,2,FALSE) -> #N/A | I33: =VLOOKUP(F33,Sp_score_ref!$A$2:$C$1517,3,FALSE) -> #N/A | K33: =IF($I33 = "A", 1, "0") -> #N/A | L33: =IF(AND($I33 = "A", $G33 <> 2), 1, "0") -> #N/A | M33: =IF(AND($I33 = "A", $G33 <> 1), 1, "0") -> #N/A | N33: =IF($I33 = "B", 1, "0") -> #N/A | O33: =IF(AND($I33 = "B", $G33 <> 2), 1, "0") -> #N/A | P33: =IF(AND($I33 = "B", $G33 <> 1), 1, "0") -> #N/A | Q33: =IF($I33 = "C", 1, "0") -> #N/A | R33: =IF(AND($I33 = "C", $G33 <> 2), 1, "0") -> #N/A | S33: =IF(AND($I33 = "C", $G33 <> 1), 1, "0") -> #N/A | T33: =IF($I33 = "X", 1, "0") -> #N/A | U33: =IF(AND($I33 = "X", $G33 <> 2), 1, "0") -> #N/A | V33: =IF(AND($I33 = "X", $G33 <> 1), 1, "0") -> #N/A | W33: =IF($I33 = "Y", 1, "0") -> #N/A | X33: =IF(AND($I33 = "Y", $G33 <> 2), 1, "0") -> #N/A | Y33: =IF(AND($I33 = "Y", $G33 <> 1), 1, "0") -> #N/A | Z33: =IF($I33 = "Z", 1, "0") -> #N/A | AA33: =IF(AND($I33 = "Z", $G33 <> 2), 1, "0") -> #N/A | AB33: =IF(AND($I33 = "Z", $G33 <> 1), 1, "0") -> #N/A
C34: Cryptogam (% cover) | H34: =VLOOKUP(F34,Sp_score_ref!$A$2:$C$1517,2,FALSE) -> #N/A | I34: =VLOOKUP(F34,Sp_score_ref!$A$2:$C$1517,3,FALSE) -> #N/A | K34: =IF($I34 = "A", 1, "0") -> #N/A | L34: =IF(AND($I34 = "A", $G34 <> 2), 1, "0") -> #N/A | M34: =IF(AND($I34 = "A", $G34 <> 1), 1, "0") -> #N/A | N34: =IF($I34 = "B", 1, "0") -> #N/A | O34: =IF(AND($I34 = "B", $G34 <> 2), 1, "0") -> #N/A | P34: =IF(AND($I34 = "B", $G34 <> 1), 1, "0") -> #N/A | Q34: =IF($I34 = "C", 1, "0") -> #N/A | R34: =IF(AND($I34 = "C", $G34 <> 2), 1, "0") -> #N/A | S34: =IF(AND($I34 = "C", $G34 <> 1), 1, "0") -> #N/A | T34: =IF($I34 = "X", 1, "0") -> #N/A | U34: =IF(AND($I34 = "X", $G34 <> 2), 1, "0") -> #N/A | V34: =IF(AND($I34 = "X", $G34 <> 1), 1, "0") -> #N/A | W34: =IF($I34 = "Y", 1, "0") -> #N/A | X34: =IF(AND($I34 = "Y", $G34 <> 2), 1, "0") -> #N/A | Y34: =IF(AND($I34 = "Y", $G34 <> 1), 1, "0") -> #N/A | Z34: =IF($I34 = "Z", 1, "0") -> #N/A | AA34: =IF(AND($I34 = "Z", $G34 <> 2), 1, "0") -> #N/A | AB34: =IF(AND($I34 = "Z", $G34 <> 1), 1, "0") -> #N/A
C35: * | H35: =VLOOKUP(F35,Sp_score_ref!$A$2:$C$1517,2,FALSE) -> #N/A | I35: =VLOOKUP(F35,Sp_score_ref!$A$2:$C$1517,3,FALSE) -> #N/A | K35: =IF($I35 = "A", 1, "0") -> #N/A | L35: =IF(AND($I35 = "A", $G35 <> 2), 1, "0") -> #N/A | M35: =IF(AND($I35 = "A", $G35 <> 1), 1, "0") -> #N/A | N35: =IF($I35 = "B", 1, "0") -> #N/A | O35: =IF(AND($I35 = "B", $G35 <> 2), 1, "0") -> #N/A | P35: =IF(AND($I35 = "B", $G35 <> 1), 1, "0") -> #N/A | Q35: =IF($I35 = "C", 1, "0") -> #N/A | R35: =IF(AND($I35 = "C", $G35 <> 2), 1, "0") -> #N/A | S35: =IF(AND($I35 = "C", $G35 <> 1), 1, "0") -> #N/A | T35: =IF($I35 = "X", 1, "0") -> #N/A | U35: =IF(AND($I35 = "X", $G35 <> 2), 1, "0") -> #N/A | V35: =IF(AND($I35 = "X", $G35 <> 1), 1, "0") -> #N/A | W35: =IF($I35 = "Y", 1, "0") -> #N/A | X35: =IF(AND($I35 = "Y", $G35 <> 2), 1, "0") -> #N/A | Y35: =IF(AND($I35 = "Y", $G35 <> 1), 1, "0") -> #N/A | Z35: =IF($I35 = "Z", 1, "0") -> #N/A | AA35: =IF(AND($I35 = "Z", $G35 <> 2), 1, "0") -> #N/A | AB35: =IF(AND($I35 = "Z", $G35 <> 1), 1, "0") -> #N/A
C36: Woody debris (linear m) | H36: =VLOOKUP(F36,Sp_score_ref!$A$2:$C$1517,2,FALSE) -> #N/A | I36: =VLOOKUP(F36,Sp_score_ref!$A$2:$C$1517,3,FALSE) -> #N/A | K36: =IF($I36 = "A", 1, "0") -> #N/A | L36: =IF(AND($I36 = "A", $G36 <> 2), 1, "0") -> #N/A | M36: =IF(AND($I36 = "A", $G36 <> 1), 1, "0") -> #N/A | N36: =IF($I36 = "B", 1, "0") -> #N/A | O36: =IF(AND($I36 = "B", $G36 <> 2), 1, "0") -> #N/A | P36: =IF(AND($I36 = "B", $G36 <> 1), 1, "0") -> #N/A | Q36: =IF($I36 = "C", 1, "0") -> #N/A | R36: =IF(AND($I36 = "C", $G36 <> 2), 1, "0") -> #N/A | S36: =IF(AND($I36 = "C", $G36 <> 1), 1, "0") -> #N/A | T36: =IF($I36 = "X", 1, "0") -> #N/A | U36: =IF(AND($I36 = "X", $G36 <> 2), 1, "0") -> #N/A | V36: =IF(AND($I36 = "X", $G36 <> 1), 1, "0") -> #N/A | W36: =IF($I36 = "Y", 1, "0") -> #N/A | X36: =IF(AND($I36 = "Y", $G36 <> 2), 1, "0") -> #N/A | Y36: =IF(AND($I36 = "Y", $G36 <> 1), 1, "0") -> #N/A | Z36: =IF($I36 = "Z", 1, "0") -> #N/A | AA36: =IF(AND($I36 = "Z", $G36 <> 2), 1, "0") -> #N/A | AB36: =IF(AND($I36 = "Z", $G36 <> 1), 1, "0") -> #N/A
C37: Woody regeneration (no. spp.) | H37: =VLOOKUP(F37,Sp_score_ref!$A$2:$C$1517,2,FALSE) -> #N/A | I37: =VLOOKUP(F37,Sp_score_ref!$A$2:$C$1517,3,FALSE) -> #N/A | K37: =IF($I37 = "A", 1, "0") -> #N/A | L37: =IF(AND($I37 = "A", $G37 <> 2), 1, "0") -> #N/A | M37: =IF(AND($I37 = "A", $G37 <> 1), 1, "0") -> #N/A | N37: =IF($I37 = "B", 1, "0") -> #N/A | O37: =IF(AND($I37 = "B", $G37 <> 2), 1, "0") -> #N/A | P37: =IF(AND($I37 = "B", $G37 <> 1), 1, "0") -> #N/A | Q37: =IF($I37 = "C", 1, "0") -> #N/A | R37: =IF(AND($I37 = "C", $G37 <> 2), 1, "0") -> #N/A | S37: =IF(AND($I37 = "C", $G37 <> 1), 1, "0") -> #N/A | T37: =IF($I37 = "X", 1, "0") -> #N/A | U37: =IF(AND($I37 = "X", $G37 <> 2), 1, "0") -> #N/A | V37: =IF(AND($I37 = "X", $G37 <> 1), 1, "0") -> #N/A | W37: =IF($I37 = "Y", 1, "0") -> #N/A | X37: =IF(AND($I37 = "Y", $G37 <> 2), 1, "0") -> #N/A | Y37: =IF(AND($I37 = "Y", $G37 <> 1), 1, "0") -> #N/A | Z37: =IF($I37 = "Z", 1, "0") -> #N/A | AA37: =IF(AND($I37 = "Z", $G37 <> 2), 1, "0") -> #N/A | AB37: =IF(AND($I37 = "Z", $G37 <> 1), 1, "0") -> #N/A
C38: Woody regeneration (abund.) | H38: =VLOOKUP(F38,Sp_score_ref!$A$2:$C$1517,2,FALSE) -> #N/A | I38: =VLOOKUP(F38,Sp_score_ref!$A$2:$C$1517,3,FALSE) -> #N/A | K38: =IF($I38 = "A", 1, "0") -> #N/A | L38: =IF(AND($I38 = "A", $G38 <> 2), 1, "0") -> #N/A | M38: =IF(AND($I38 = "A", $G38 <> 1), 1, "0") -> #N/A | N38: =IF($I38 = "B", 1, "0") -> #N/A | O38: =IF(AND($I38 = "B", $G38 <> 2), 1, "0") -> #N/A | P38: =IF(AND($I38 = "B", $G38 <> 1), 1, "0") -> #N/A | Q38: =IF($I38 = "C", 1, "0") -> #N/A | R38: =IF(AND($I38 = "C", $G38 <> 2), 1, "0") -> #N/A | S38: =IF(AND($I38 = "C", $G38 <> 1), 1, "0") -> #N/A | T38: =IF($I38 = "X", 1, "0") -> #N/A | U38: =IF(AND($I38 = "X", $G38 <> 2), 1, "0") -> #N/A | V38: =IF(AND($I38 = "X", $G38 <> 1), 1, "0") -> #N/A | W38: =IF($I38 = "Y", 1, "0") -> #N/A | X38: =IF(AND($I38 = "Y", $G38 <> 2), 1, "0") -> #N/A | Y38: =IF(AND($I38 = "Y", $G38 <> 1), 1, "0") -> #N/A | Z38: =IF($I38 = "Z", 1, "0") -> #N/A | AA38: =IF(AND($I38 = "Z", $G38 <> 2), 1, "0") -> #N/A | AB38: =IF(AND($I38 = "Z", $G38 <> 1), 1, "0") -> #N/A
C39: Rocks - surface (cover %) | H39: =VLOOKUP(F39,Sp_score_ref!$A$2:$C$1517,2,FALSE) -> #N/A | I39: =VLOOKUP(F39,Sp_score_ref!$A$2:$C$1517,3,FALSE) -> #N/A | K39: =IF($I39 = "A", 1, "0") -> #N/A | L39: =IF(AND($I39 = "A", $G39 <> 2), 1, "0") -> #N/A | M39: =IF(AND($I39 = "A", $G39 <> 1), 1, "0") -> #N/A | N39: =IF($I39 = "B", 1, "0") -> #N/A | O39: =IF(AND($I39 = "B", $G39 <> 2), 1, "0") -> #N/A | P39: =IF(AND($I39 = "B", $G39 <> 1), 1, "0") -> #N/A | Q39: =IF($I39 = "C", 1, "0") -> #N/A | R39: =IF(AND($I39 = "C", $G39 <> 2), 1, "0") -> #N/A | S39: =IF(AND($I39 = "C", $G39 <> 1), 1, "0") -> #N/A | T39: =IF($I39 = "X", 1, "0") -> #N/A | U39: =IF(AND($I39 = "X", $G39 <> 2), 1, "0") -> #N/A | V39: =IF(AND($I39 = "X", $G39 <> 1), 1, "0") -> #N/A | W39: =IF($I39 = "Y", 1, "0") -> #N/A | X39: =IF(AND($I39 = "Y", $G39 <> 2), 1, "0") -> #N/A | Y39: =IF(AND($I39 = "Y", $G39 <> 1), 1, "0") -> #N/A | Z39: =IF($I39 = "Z", 1, "0") -> #N/A | AA39: =IF(AND($I39 = "Z", $G39 <> 2), 1, "0") -> #N/A | AB39: =IF(AND($I39 = "Z", $G39 <> 1), 1, "0") -> #N/A
C40: Rocks - outcropping (cover %) | H40: =VLOOKUP(F40,Sp_score_ref!$A$2:$C$1517,2,FALSE) -> #N/A | I40: =VLOOKUP(F40,Sp_score_ref!$A$2:$C$1517,3,FALSE) -> #N/A | K40: =IF($I40 = "A", 1, "0") -> #N/A | L40: =IF(AND($I40 = "A", $G40 <> 2), 1, "0") -> #N/A | M40: =IF(AND($I40 = "A", $G40 <> 1), 1, "0") -> #N/A | N40: =IF($I40 = "B", 1, "0") -> #N/A | O40: =IF(AND($I40 = "B", $G40 <> 2), 1, "0") -> #N/A | P40: =IF(AND($I40 = "B", $G40 <> 1), 1, "0") -> #N/A | Q40: =IF($I40 = "C", 1, "0") -> #N/A | R40: =IF(AND($I40 = "C", $G40 <> 2), 1, "0") -> #N/A | S40: =IF(AND($I40 = "C", $G40 <> 1), 1, "0") -> #N/A | T40: =IF($I40 = "X", 1, "0") -> #N/A | U40: =IF(AND($I40 = "X", $G40 <> 2), 1, "0") -> #N/A | V40: =IF(AND($I40 = "X", $G40 <> 1), 1, "0") -> #N/A | W40: =IF($I40 = "Y", 1, "0") -> #N/A | X40: =IF(AND($I40 = "Y", $G40 <> 2), 1, "0") -> #N/A | Y40: =IF(AND($I40 = "Y", $G40 <> 1), 1, "0") -> #N/A | Z40: =IF($I40 = "Z", 1, "0") -> #N/A | AA40: =IF(AND($I40 = "Z", $G40 <> 2), 1, "0") -> #N/A | AB40: =IF(AND($I40 = "Z", $G40 <> 1), 1, "0") -> #N/A
C41: Note 1: The above data are consistent with the NSW Vegetation Information Standards | H41: =VLOOKUP(F41,Sp_score_ref!$A$2:$C$1517,2,FALSE) -> #N/A | I41: =VLOOKUP(F41,Sp_score_ref!$A$2:$C$1517,3,FALSE) -> #N/A | K41: =IF($I41 = "A", 1, "0") -> #N/A | L41: =IF(AND($I41 = "A", $G41 <> 2), 1, "0") -> #N/A | M41: =IF(AND($I41 = "A", $G41 <> 1), 1, "0") -> #N/A | N41: =IF($I41 = "B", 1, "0") -> #N/A | O41: =IF(AND($I41 = "B", $G41 <> 2), 1, "0") -> #N/A | P41: =IF(AND($I41 = "B", $G41 <> 1), 1, "0") -> #N/A | Q41: =IF($I41 = "C", 1, "0") -> #N/A | R41: =IF(AND($I41 = "C", $G41 <> 2), 1, "0") -> #N/A | S41: =IF(AND($I41 = "C", $G41 <> 1), 1, "0") -> #N/A | T41: =IF($I41 = "X", 1, "0") -> #N/A | U41: =IF(AND($I41 = "X", $G41 <> 2), 1, "0") -> #N/A | V41: =IF(AND($I41 = "X", $G41 <> 1), 1, "0") -> #N/A | W41: =IF($I41 = "Y", 1, "0") -> #N/A | X41: =IF(AND($I41 = "Y", $G41 <> 2), 1, "0") -> #N/A | Y41: =IF(AND($I41 = "Y", $G41 <> 1), 1, "0") -> #N/A | Z41: =IF($I41 = "Z", 1, "0") -> #N/A | AA41: =IF(AND($I41 = "Z", $G41 <> 2), 1, "0") -> #N/A | AB41: =IF(AND($I41 = "Z", $G41 <> 1), 1, "0") -> #N/A
H42: =VLOOKUP(F42,Sp_score_ref!$A$2:$C$1517,2,FALSE) -> #N/A | I42: =VLOOKUP(F42,Sp_score_ref!$A$2:$C$1517,3,FALSE) -> #N/A | K42: =IF($I42 = "A", 1, "0") -> #N/A | L42: =IF(AND($I42 = "A", $G42 <> 2), 1, "0") -> #N/A | M42: =IF(AND($I42 = "A", $G42 <> 1), 1, "0") -> #N/A | N42: =IF($I42 = "B", 1, "0") -> #N/A | O42: =IF(AND($I42 = "B", $G42 <> 2), 1, "0") -> #N/A | P42: =IF(AND($I42 = "B", $G42 <> 1), 1, "0") -> #N/A | Q42: =IF($I42 = "C", 1, "0") -> #N/A | R42: =IF(AND($I42 = "C", $G42 <> 2), 1, "0") -> #N/A | S42: =IF(AND($I42 = "C", $G42 <> 1), 1, "0") -> #N/A | T42: =IF($I42 = "X", 1, "0") -> #N/A | U42: =IF(AND($I42 = "X", $G42 <> 2), 1, "0") -> #N/A | V42: =IF(AND($I42 = "X", $G42 <> 1), 1, "0") -> #N/A | W42: =IF($I42 = "Y", 1, "0") -> #N/A | X42: =IF(AND($I42 = "Y", $G42 <> 2), 1, "0") -> #N/A | Y42: =IF(AND($I42 = "Y", $G42 <> 1), 1, "0") -> #N/A | Z42: =IF($I42 = "Z", 1, "0") -> #N/A | AA42: =IF(AND($I42 = "Z", $G42 <> 2), 1, "0") -> #N/A | AB42: =IF(AND($I42 = "Z", $G42 <> 1), 1, "0") -> #N/A
C43: Note 2: The above values do not contribute to the site's Floristic Value Score | H43: =VLOOKUP(F43,Sp_score_ref!$A$2:$C$1517,2,FALSE) -> #N/A | I43: =VLOOKUP(F43,Sp_score_ref!$A$2:$C$1517,3,FALSE) -> #N/A | K43: =IF($I43 = "A", 1, "0") -> #N/A | L43: =IF(AND($I43 = "A", $G43 <> 2), 1, "0") -> #N/A | M43: =IF(AND($I43 = "A", $G43 <> 1), 1, "0") -> #N/A | N43: =IF($I43 = "B", 1, "0") -> #N/A | O43: =IF(AND($I43 = "B", $G43 <> 2), 1, "0") -> #N/A | P43: =IF(AND($I43 = "B", $G43 <> 1), 1, "0") -> #N/A | Q43: =IF($I43 = "C", 1, "0") -> #N/A | R43: =IF(AND($I43 = "C", $G43 <> 2), 1, "0") -> #N/A | S43: =IF(AND($I43 = "C", $G43 <> 1), 1, "0") -> #N/A | T43: =IF($I43 = "X", 1, "0") -> #N/A | U43: =IF(AND($I43 = "X", $G43 <> 2), 1, "0") -> #N/A | V43: =IF(AND($I43 = "X", $G43 <> 1), 1, "0") -> #N/A | W43: =IF($I43 = "Y", 1, "0") -> #N/A | X43: =IF(AND($I43 = "Y", $G43 <> 2), 1, "0") -> #N/A | Y43: =IF(AND($I43 = "Y", $G43 <> 1), 1, "0") -> #N/A | Z43: =IF($I43 = "Z", 1, "0") -> #N/A | AA43: =IF(AND($I43 = "Z", $G43 <> 2), 1, "0") -> #N/A | AB43: =IF(AND($I43 = "Z", $G43 <> 1), 1, "0") -> #N/A
...

Sheet Sp_score_ref
A1: CODE NAMES - see instructions at right where these are not unique, or if just the genus name is recorded, or if the species has various Significance Ratings according to cover, see explanation in column H. | B1: SCIENTIFIC NAMES | C1: Significance Rating | D1: Rationale (see Instruction Manual) | F1: See below for instructions on entering species codes
A2: abut fras | B2: Abutilon fraseri | C2: A | D2: Sensitive tree, shrub or climber
A3: abut oxyc | B3: Abutilon oxycarpum | C3: A | D3: Sensitive tree, shrub or climber | F3: Things to remember when entering data
A4: acac acin | B4: Acacia acinacea | C4: A | D4: =D40 -> Sensitive pea (Fabaceae) | F4: o | G4: Use the 4 letters of genus and species (4 + 4), unless the species are the following:
A5: acac aspe | B5: Acacia aspera | C5: A | D5: Sensitive pea (Fabaceae) | G5: . If only genus is known, then in many cases, they can be entered as just the genus name, thus: "swainsona" for "Swainsona sp.", but only if the Significance Ratings are uniform across the genus
A6: acac bail (non-natural population) | B6: Acacia baileyana (derived from escaped or planted plants and not within the natural population based in and around the Cootamundra ditrict) | C6: Y
A7: acac bail (natural population) | B7: Acacia baileyana (part of the natural population based in and around the Cootamundra ditrict) | C7: A | D7: Sensitive pea (Fabaceae) | G7: . If the genus name has only 3 letters (i.e., Poa)
A8: acac brac | B8: Acacia brachybotrya | C8: A | D8: Sensitive pea (Fabaceae) | G8: . If 4 + 4 letter codes are not unique, then it's advised to type in the full name as in "brunonia australis", or "brunoniella australis"
A9: acac brow | B9: Acacia brownii | C9: A | D9: Sensitive pea (Fabaceae) | G9: . For genera with native and exotic species if not identified, these may have different Significance Ratings, for instructions see below
A10: acac buxi | B10: Acacia buxifolia | C10: A | D10: Sensitive pea (Fabaceae) | F10: o | G10: If native and exotic species in a genus cannot be identified, but it contains both native and exotic species, then use the code format, e.g., for Geranium spp., use "Gera spn" for a native species and "Gera spe" for an exotic species
A11: acac caes | B11: Acacia caesiella | C11: A | D11: Sensitive pea (Fabaceae)
A12: acac card | B12: Acacia cardiophylla | C12: A | D12: Sensitive pea (Fabaceae) | F12: o | G12: In many multi-species native genera, when it is difficult to assign your plant to a species, and if all species in the genus have the same Significance Rating, then type in the full genus name (e.g. caladenia) and the name returned will be Caladenia sp.
A13: acac chee | B13: Acacia cheelii | C13: A | D13: Sensitive pea (Fabaceae)
A14: acac deal | B14: Acacia dealbata | C14: A | D14: Sensitive pea (Fabaceae)
A15: acac dean | B15: Acacia deanei | C15: A | D15: Sensitive pea (Fabaceae) | F15: o | G15: Note: if the ID is only to the species level and the tool returns a *, and no score is returned, this means that the codes are different for the different species within the genus. You can search for the genus names in Sp_score_ref, and chose a similar species to return a score if you're reasonably certain that the species in question has a similar response to one of those other species (i.e., a similar Significance Rating).
A16: acac debi | B16: Acacia debilis | C16: A | D16: Sensitive pea (Fabaceae)
A17: acac deco | B17: Acacia decora | C17: A | D17: Sensitive pea (Fabaceae)
A18: acac decu | B18: Acacia decurrens | C18: A | D18: Sensitive pea (Fabaceae) | F18: o | G18: Nomenclature: all plant names are as in PlantNet (as of May 2022). If older names are used then they won't register. To look up current names in PlantNet, tick the "Show synonyms" box on the search page at: http://plantnet.rbgsyd.nsw.gov.au/search/simple.htm. If new synonyms are subsequently introduced, then use the old names, as in this spreadsheet, or update this spreadsheet with newer names as they appear.
A19: acac dora | B19: Acacia doratoxylon | C19: A | D19: Sensitive pea (Fabaceae)
A20: acac doro | B20: Acacia dorothea | C20: A | D20: Sensitive pea (Fabaceae)
A21: acacia falcata | B21: Acacia falcata | C21: A | D21: Sensitive pea (Fabaceae) | F21: o | G21: If entering additional species into this spreadsheet (i.e., species that don't appear in the column to the left, on THIS page), then select a row within the body of the list and enter rows above the selection, as required. Each new species should have a significance rating assigned to it; expert advice may be required to assign significance ratings. Should you add new species and developing new ratings for them, please send this information, including a short note on justification, to Rainer Rehwinkel by email: rainer.rehwinkel@hotmail.com.
A22: acacia falciformis | B22: Acacia falciformis | C22: A | D22: Sensitive pea (Fabaceae)
A23: acac fili | B23: Acacia filicifolia | C23: A | D23: Sensitive pea (Fabaceae)
A24: acac flex | B24: Acacia flexifolia | C24: A | D24: Sensitive pea (Fabaceae)
A25: acac geni | B25: Acacia genistifolia | C25: A | D25: Sensitive pea (Fabaceae) | F25: o | G25: Subspecies are not considered separately, because not enough is known about their individual responses.
A26: acac glad | B26: Acacia gladiiformis | C26: A | D26: Sensitive pea (Fabaceae) | F26: o | G26: In some cases, widely planted native species may occur in a site, mostly by having been planted, or in some less common examples, by invading from neighboring plantings or gardens. It is advisable to check to determine whether the species in question falls into this category. Check for out-of-range Grevillea, Callistemon, Melaleuca, Leptospermum and Eucalyptus spp. (amongst others).
A27: acac gunn | B27: Acacia gunnii | C27: A | D27: Sensitive pea (Fabaceae)
A28: acac hake | B28: Acacia hakeoides | C28: A | D28: Sensitive pea (Fabaceae)
A29: acac impl | B29: Acacia implexa | C29: A | D29: Sensitive pea (Fabaceae)
A30: acac ixio | B30: Acacia ixiophylla | C30: A | D30: Sensitive pea (Fabaceae)
A31: acac ixod | B31: Acacia ixodes | C31: A | D31: Sensitive pea (Fabaceae)
A32: acac kybe | B32: Acacia kybeanensis | C32: A | D32: Sensitive pea (Fabaceae)
A33: acac lani | B33: Acacia lanigera | C33: A | D33: Sensitive pea (Fabaceae)
A34: acac leio | B34: Acacia leiocalyx | C34: A | D34: Sensitive pea (Fabaceae)
A35: acac leuc | B35: Acacia leucoclada | C35: A | D35: Sensitive pea (Fabaceae)
A36: acac line | B36: Acacia linearifolia | C36: A | D36: Sensitive pea (Fabaceae)
A37: acac mear | B37: Acacia mearnsii | C37: A | D37: Sensitive pea (Fabaceae)
A38: acac mela | B38: Acacia melanoxylon | C38: A | D38: Sensitive pea (Fabaceae)
... A49: acac penn | B49: Acacia penninervis | C49: A | D49: Sensitive pea (Fabaceae)
A50: acac poda | B50: Acacia podalyriifolia | C50: Y
...
